Workbook

Sheet diagnosis
A1: DiagnosisID | B1: DiagnosisName
A2: 1 | B2: Hypertension
A3: 2 | B3: Diabetes
A4: 3 | B4: Heart Disease
A5: 4 | B5: Asthma
A6: 5 | B6: Stroke
A7: 6 | B7: COPD
A8: 7 | B8: Cancer
A9: 8 | B9: Arthritis
A10: 9 | B10: Kidney Disease
A11: 10 | B11: Liver Disease

Sheet patients
A1: PatientID | B1: Name | C1: Age | D1: Gender | E1: DiagnosisID | F1: AdmissionDate | G1: DischargeDate | H1: OutcomeID | I1: TreatmentCost | K1: DiagnosisName | L1: OutcomeName | M1: Length of Stay | N1: Disease | O1: Risk Score
A2: 1 | B2: Edward Montes | C2: 68 | D2: M | E2: 2 | F2: 45738 | G2: 45751 | H2: 1 | I2: 4443 | K2: =VLOOKUP(E2,diagnosis!$A$1:$B$11,2,FALSE) -> Diabetes | L2: =VLOOKUP(H2,outcomes!$A$1:$B$4,2,FALSE) -> Recovered | M2: =DATEDIF(F2,G2,"d") -> 13 | N2: =VLOOKUP(A2,labs!$A$2:$E$201,3,FALSE) -> Blood Pressure | O2: =IF(OR(C2>65,H2<>1),"High Risk","Low Risk") -> High Risk
A3: 2 | B3: Jessica Zimmerman | C3: 81 | D3: M | E3: 2 | F3: 45747 | G3: 45749 | H3: 2 | I3: 4265 | K3: =VLOOKUP(E3,diagnosis!$A$1:$B$11,2,FALSE) -> Diabetes | L3: =VLOOKUP(H3,outcomes!$A$1:$B$4,2,FALSE) -> Complicated | M3: =DATEDIF(F3,G3,"d") -> 2 | N3: =VLOOKUP(A3,labs!$A$2:$E$201,3,FALSE) -> Cholesterol | O3: =IF(OR(C3>65,H3<>1),"High Risk","Low Risk") -> High Risk
A4: 3 | B4: Gina Alexander | C4: 58 | D4: M | E4: 6 | F4: 45665 | G4: 45729 | H4: 1 | I4: 4188 | K4: =VLOOKUP(E4,diagnosis!$A$1:$B$11,2,FALSE) -> COPD | L4: =VLOOKUP(H4,outcomes!$A$1:$B$4,2,FALSE) -> Recovered | M4: =DATEDIF(F4,G4,"d") -> 64 | N4: =VLOOKUP(A4,labs!$A$2:$E$201,3,FALSE) -> Blood Pressure | O4: =IF(OR(C4>65,H4<>1),"High Risk","Low Risk") -> Low Risk
A5: 4 | B5: Lori Green | C5: 44 | D5: F | E5: 3 | F5: 45750 | G5: 45752 | H5: 1 | I5: 9783 | K5: =VLOOKUP(E5,diagnosis!$A$1:$B$11,2,FALSE) -> Heart Disease | L5: =VLOOKUP(H5,outcomes!$A$1:$B$4,2,FALSE) -> Recovered | M5: =DATEDIF(F5,G5,"d") -> 2 | N5: =VLOOKUP(A5,labs!$A$2:$E$201,3,FALSE) -> Cholesterol | O5: =IF(OR(C5>65,H5<>1),"High Risk","Low Risk") -> Low Risk
A6: 5 | B6: Jack Logan | C6: 72 | D6: F | E6: 9 | F6: 45811 | G6: 45812 | H6: 1 | I6: 5005 | K6: =VLOOKUP(E6,diagnosis!$A$1:$B$11,2,FALSE) -> Kidney Disease | L6: =VLOOKUP(H6,outcomes!$A$1:$B$4,2,FALSE) -> Recovered | M6: =DATEDIF(F6,G6,"d") -> 1 | N6: =VLOOKUP(A6,labs!$A$2:$E$201,3,FALSE) -> Blood Sugar | O6: =IF(OR(C6>65,H6<>1),"High Risk","Low Risk") -> High Risk
A7: 6 | B7: Melinda Robinson | C7: 37 | D7: F | E7: 4 | F7: 45747 | G7: 45752 | H7: 1 | I7: 5281 | K7: =VLOOKUP(E7,diagnosis!$A$1:$B$11,2,FALSE) -> Asthma | L7: =VLOOKUP(H7,outcomes!$A$1:$B$4,2,FALSE) -> Recovered | M7: =DATEDIF(F7,G7,"d") -> 5 | N7: =VLOOKUP(A7,labs!$A$2:$E$201,3,FALSE) -> Creatinine | O7: =IF(OR(C7>65,H7<>1),"High Risk","Low Risk") -> Low Risk
A8: 7 | B8: Sherry Robinson | C8: 50 | D8: F | E8: 1 | F8: 45819 | G8: 45843 | H8: 2 | I8: 2984 | K8: =VLOOKUP(E8,diagnosis!$A$1:$B$11,2,FALSE) -> Hypertension | L8: =VLOOKUP(H8,outcomes!$A$1:$B$4,2,FALSE) -> Complicated | M8: =DATEDIF(F8,G8,"d") -> 24 | N8: =VLOOKUP(A8,labs!$A$2:$E$201,3,FALSE) -> Blood Pressure | O8: =IF(OR(C8>65,H8<>1),"High Risk","Low Risk") -> High Risk
A9: 8 | B9: James Watts | C9: 68 | D9: M | E9: 4 | F9: 45772 | G9: 45827 | H9: 1 | I9: 9136 | K9: =VLOOKUP(E9,diagnosis!$A$1:$B$11,2,FALSE) -> Asthma | L9: =VLOOKUP(H9,outcomes!$A$1:$B$4,2,FALSE) -> Recovered | M9: =DATEDIF(F9,G9,"d") -> 55 | N9: =VLOOKUP(A9,labs!$A$2:$E$201,3,FALSE) -> Hemoglobin | O9: =IF(OR(C9>65,H9<>1),"High Risk","Low Risk") -> High Risk
A10: 9 | B10: Jeanne Butler | C10: 87 | D10: F | E10: 1 | F10: 45762 | G10: 45764 | H10: 2 | I10: 9790 | K10: =VLOOKUP(E10,diagnosis!$A$1:$B$11,2,FALSE) -> Hypertension | L10: =VLOOKUP(H10,outcomes!$A$1:$B$4,2,FALSE) -> Complicated | M10: =DATEDIF(F10,G10,"d") -> 2 | N10: =VLOOKUP(A10,labs!$A$2:$E$201,3,FALSE) -> Hemoglobin | O10: =IF(OR(C10>65,H10<>1),"High Risk","Low Risk") -> High Risk
A11: 10 | B11: Benjamin Rogers | C11: 48 | D11: M | E11: 5 | F11: 45792 | G11: 45796 | H11: 2 | I11: 3639 | K11: =VLOOKUP(E11,diagnosis!$A$1:$B$11,2,FALSE) -> Stroke | L11: =VLOOKUP(H11,outcomes!$A$1:$B$4,2,FALSE) -> Complicated | M11: =DATEDIF(F11,G11,"d") -> 4 | N11: =VLOOKUP(A11,labs!$A$2:$E$201,3,FALSE) -> Vitamin D | O11: =IF(OR(C11>65,H11<>1),"High Risk","Low Risk") -> High Risk
A12: 11 | B12: Carol Sanchez | C12: 52 | D12: M | E12: 4 | F12: 45715 | G12: 45765 | H12: 3 | I12: 2827 | K12: =VLOOKUP(E12,diagnosis!$A$1:$B$11,2,FALSE) -> Asthma | L12: =VLOOKUP(H12,outcomes!$A$1:$B$4,2,FALSE) -> Deceased | M12: =DATEDIF(F12,G12,"d") -> 50 | N12: =VLOOKUP(A12,labs!$A$2:$E$201,3,FALSE) -> Cholesterol | O12: =IF(OR(C12>65,H12<>1),"High Risk","Low Risk") -> High Risk
A13: 12 | B13: Stacy Clark | C13: 40 | D13: F | E13: 8 | F13: 45771 | G13: 45795 | H13: 2 | I13: 4730 | K13: =VLOOKUP(E13,diagnosis!$A$1:$B$11,2,FALSE) -> Arthritis | L13: =VLOOKUP(H13,outcomes!$A$1:$B$4,2,FALSE) -> Complicated | M13: =DATEDIF(F13,G13,"d") -> 24 | N13: =VLOOKUP(A13,labs!$A$2:$E$201,3,FALSE) -> Blood Pressure | O13: =IF(OR(C13>65,H13<>1),"High Risk","Low Risk") -> High Risk
... A15: 14 | B15: Cody Ryan | C15: 53 | D15: F | E15: 7 | F15: 45814 | G15: 45818 | H15: 2 | I15: 9147 | K15: =VLOOKUP(E15,diagnosis!$A$1:$B$11,2,FALSE) -> Cancer | L15: =VLOOKUP(H15,outcomes!$A$1:$B$4,2,FALSE) -> Complicated | M15: =DATEDIF(F15,G15,"d") -> 4 | N15: =VLOOKUP(A15,labs!$A$2:$E$201,3,FALSE) -> Blood Pressure | O15: =IF(OR(C15>65,H15<>1),"High Risk","Low Risk") -> High Risk
A16: 15 | B16: Kimberly Alexander | C16: 82 | D16: F | E16: 3 | F16: 45777 | G16: 45780 | H16: 2 | I16: 6451 | K16: =VLOOKUP(E16,diagnosis!$A$1:$B$11,2,FALSE) -> Heart Disease | L16: =VLOOKUP(H16,outcomes!$A$1:$B$4,2,FALSE) -> Complicated | M16: =DATEDIF(F16,G16,"d") -> 3 | N16: =VLOOKUP(A16,labs!$A$2:$E$201,3,FALSE) -> Cholesterol
A17: 16 | B17: Olivia Roy | C17: 65 | D17: F | E17: 1 | F17: 45821 | G17: 45823 | H17: 2 | I17: 9151 | K17: =VLOOKUP(E17,diagnosis!$A$1:$B$11,2,FALSE) -> Hypertension | L17: =VLOOKUP(H17,outcomes!$A$1:$B$4,2,FALSE) -> Complicated | M17: =DATEDIF(F17,G17,"d") -> 2 | N17: =VLOOKUP(A17,labs!$A$2:$E$201,3,FALSE) -> Hemoglobin
A18: 17 | B18: Sabrina Medina | C18: 69 | D18: F | E18: 1 | F18: 45678 | G18: 45799 | H18: 3 | I18: 7443 | K18: =VLOOKUP(E18,diagnosis!$A$1:$B$11,2,FALSE) -> Hypertension | M18: =DATEDIF(F18,G18,"d") -> 121 | N18: =VLOOKUP(A18,labs!$A$2:$E$201,3,FALSE) -> Blood Sugar
A19: 18 | B19: Jennifer Wright | C19: 53 | D19: F | E19: 3 | F19: 45821 | G19: 45830 | H19: 3 | I19: 9300 | K19: =VLOOKUP(E19,diagnosis!$A$1:$B$11,2,FALSE) -> Heart Disease | M19: =DATEDIF(F19,G19,"d") -> 9 | N19: =VLOOKUP(A19,labs!$A$2:$E$201,3,FALSE) -> Hemoglobin
A20: 19 | B20: Christian Lynch | C20: 32 | D20: F | E20: 6 | F20: 45795 | G20: 45797 | H20: 1 | I20: 4935 | K20: =VLOOKUP(E20,diagnosis!$A$1:$B$11,2,FALSE) -> COPD | M20: =DATEDIF(F20,G20,"d") -> 2 | N20: =VLOOKUP(A20,labs!$A$2:$E$201,3,FALSE) -> Vitamin D
A21: 20 | B21: Jorge Castillo | C21: 51 | D21: M | E21: 7 | F21: 45758 | G21: 45847 | H21: 3 | I21: 5876 | K21: =VLOOKUP(E21,diagnosis!$A$1:$B$11,2,FALSE) -> Cancer | M21: =DATEDIF(F21,G21,"d") -> 89 | N21: =VLOOKUP(A21,labs!$A$2:$E$201,3,FALSE) -> Creatinine
A22: 21 | B22: Nicholas Wilcox | C22: 82 | D22: F | E22: 6 | F22: 45809 | G22: 45819 | H22: 3 | I22: 7959 | K22: =VLOOKUP(E22,diagnosis!$A$1:$B$11,2,FALSE) -> COPD | M22: =DATEDIF(F22,G22,"d") -> 10 | N22: =VLOOKUP(A22,labs!$A$2:$E$201,3,FALSE) -> Blood Sugar
A23: 22 | B23: Toni Gomez | C23: 31 | D23: F | E23: 6 | F23: 45834 | G23: 45841 | H23: 3 | I23: 2126 | K23: =VLOOKUP(E23,diagnosis!$A$1:$B$11,2,FALSE) -> COPD | M23: =DATEDIF(F23,G23,"d") -> 7 | N23: =VLOOKUP(A23,labs!$A$2:$E$201,3,FALSE) -> Vitamin D
A24: 23 | B24: Emily King | C24: 53 | D24: M | E24: 6 | F24: 45756 | G24: 45831 | H24: 3 | I24: 5177 | M24: =DATEDIF(F24,G24,"d") -> 75 | N24: =VLOOKUP(A24,labs!$A$2:$E$201,3,FALSE) -> Cholesterol
A25: 24 | B25: Jordan Harris | C25: 73 | D25: F | E25: 3 | F25: 45693 | G25: 45749 | H25: 1 | I25: 5056 | M25: =DATEDIF(F25,G25,"d") -> 56 | N25: =VLOOKUP(A25,labs!$A$2:$E$201,3,FALSE) -> Blood Sugar
A26: 25 | B26: Adriana Rogers | C26: 59 | D26: M | E26: 6 | F26: 45753 | G26: 45811 | H26: 3 | I26: 2603 | M26: =DATEDIF(F26,G26,"d") -> 58 | N26: =VLOOKUP(A26,labs!$A$2:$E$201,3,FALSE) -> Vitamin D
A27: 26 | B27: Samuel Thompson | C27: 67 | D27: M | E27: 8 | F27: 45809 | G27: 45810 | H27: 2 | I27: 9966 | M27: =DATEDIF(F27,G27,"d") -> 1 | N27: =VLOOKUP(A27,labs!$A$2:$E$201,3,FALSE) -> Cholesterol
A28: 27 | B28: Brenda Huber | C28: 31 | D28: F | E28: 2 | F28: 45808 | G28: 45809 | H28: 2 | I28: 5449 | M28: =DATEDIF(F28,G28,"d") -> 1 | N28: =VLOOKUP(A28,labs!$A$2:$E$201,3,FALSE) -> Hemoglobin
A29: 28 | B29: Brett Washington | C29: 89 | D29: M | E29: 5 | F29: 45694 | G29: 45776 | H29: 3 | I29: 8024 | M29: =DATEDIF(F29,G29,"d") -> 82 | N29: =VLOOKUP(A29,labs!$A$2:$E$201,3,FALSE) -> Creatinine
A30: 29 | B30: Katherine Gonzales | C30: 50 | D30: M | E30: 1 | F30: 45669 | G30: 45671 | H30: 3 | I30: 7109 | M30: =DATEDIF(F30,G30,"d") -> 2 | N30: =VLOOKUP(A30,labs!$A$2:$E$201,3,FALSE) -> Cholesterol
A31: 30 | B31: Jacqueline Bauer | C31: 62 | D31: M | E31: 1 | F31: 45770 | G31: 45774 | H31: 2 | I31: 6146 | M31: =DATEDIF(F31,G31,"d") -> 4 | N31: =VLOOKUP(A31,labs!$A$2:$E$201,3,FALSE) -> Blood Pressure
A32: 31 | B32: Brittany Walker | C32: 41 | D32: M | E32: 5 | F32: 45670 | G32: 45839 | H32: 2 | I32: 9196 | M32: =DATEDIF(F32,G32,"d") -> 169 | N32: =VLOOKUP(A32,labs!$A$2:$E$201,3,FALSE) -> Cholesterol
A33: 32 | B33: Tommy Atkinson | C33: 87 | D33: F | E33: 3 | F33: 45680 | G33: 45684 | H33: 1 | I33: 5533 | M33: =DATEDIF(F33,G33,"d") -> 4 | N33: =VLOOKUP(A33,labs!$A$2:$E$201,3,FALSE) -> Cholesterol
A34: 33 | B34: Miss Kathryn Mitchell | C34: 51 | D34: M | E34: 4 | F34: 45756 | G34: 45779 | H34: 2 | I34: 5367 | M34: =DATEDIF(F34,G34,"d") -> 23 | N34: =VLOOKUP(A34,labs!$A$2:$E$201,3,FALSE) -> Creatinine
A35: 34 | B35: Steven Morales | C35: 73 | D35: F | E35: 3 | F35: 45762 | G35: 45771 | H35: 2 | I35: 5368 | M35: =DATEDIF(F35,G35,"d") -> 9 | N35: =VLOOKUP(A35,labs!$A$2:$E$201,3,FALSE) -> Blood Pressure
A36: 35 | B36: Anthony Frederick | C36: 54 | D36: M | E36: 1 | F36: 45687 | G36: 45700 | H36: 3 | I36: 5797 | M36: =DATEDIF(F36,G36,"d") -> 13 | N36: =VLOOKUP(A36,labs!$A$2:$E$201,3,FALSE) -> Vitamin D
A37: 36 | B37: Beverly Dillon | C37: 78 | D37: M | E37: 1 | F37: 45674 | G37: 45758 | H37: 2 | I37: 8922 | M37: =DATEDIF(F37,G37,"d") -> 84
A38: 37 | B38: Monica Walker | C38: 56 | D38: M | E38: 5 | F38: 45770 | G38: 45780 | H38: 1 | I38: 7526 | M38: =DATEDIF(F38,G38,"d") -> 10
A39: 38 | B39: Russell Small | C39: 88 | D39: M | E39: 6 | F39: 45719 | G39: 45738 | H39: 2 | I39: 3792 | M39: =DATEDIF(F39,G39,"d") -> 19
A40: 39 | B40: Matthew Rios | C40: 71 | D40: F | E40: 3 | F40: 45741 | G40: 45742 | H40: 3 | I40: 4861 | M40: =DATEDIF(F40,G40,"d") -> 1
A41: 40 | B41: Nicole Vargas | C41: 57 | D41: F | E41: 9 | F41: 45769 | G41: 45820 | H41: 3 | I41: 7732 | M41: =DATEDIF(F41,G41,"d") -> 51
...

Sheet pivot_table
C4: Age | D4: (Multiple Items)
D6: Sum of TreatmentCost
C7: Amanda Richardson | D7: 2951
C8: Brenda Huber | D8: 5449
C9: Nancy Mcmahon | D9: 4332
C10: Shawn Burke | D10: 6064
C11: Shawna Webb | D11: 5462
C12: Shirley Spencer | D12: 2574
C13: Theodore Oliver | D13: 6858
C14: Toni Gomez | D14: 2126
C15: Grand Total | D15: 35816

Sheet outcomes
A1: OutcomeID | B1: OutcomeName
A2: 1 | B2: Recovered
A3: 2 | B3: Complicated
A4: 3 | B4: Deceased

Sheet labs
A1: LabID | B1: PatientID | C1: TestName | D1: Result | E1: NormalRange | G1: DiagnosisName
A2: 1 | B2: 196 | C2: Blood Pressure | D2: 89.7 | E2: 150-200
A3: 2 | B3: 165 | C3: Cholesterol | D3: 270.2 | E3: 13-17
A4: 3 | B4: 182 | C4: Blood Pressure | D4: 268 | E4: 0.6-1.2
A5: 4 | B5: 142 | C5: Cholesterol | D5: 57.3 | E5: 150-200
A6: 5 | B6: 55 | C6: Blood Sugar | D6: 256.5 | E6: 120/80
A7: 6 | B7: 176 | C7: Creatinine | D7: 82.2 | E7: 120/80
A8: 7 | B8: 7 | C8: Blood Pressure | D8: 133.8 | E8: 150-200
A9: 8 | B9: 74 | C9: Hemoglobin | D9: 235.9 | E9: 0.6-1.2
A10: 9 | B10: 7 | C10: Hemoglobin | D10: 90.2 | E10: 20-50
A11: 10 | B11: 161 | C11: Vitamin D | D11: 254.5 | E11: 13-17
A12: 11 | B12: 151 | C12: Cholesterol | D12: 258 | E12: 120/80
A13: 12 | B13: 85 | C13: Blood Pressure | D13: 176.9 | E13: 20-50
... A201: 200 | B201: 116 | C201: Hemoglobin | D201: 268.4 | E201: 150-200
